<?xml version="1.0" encoding="UTF-8"?>

<robot name="fanuc">
    <link name="base_link">
        <visual>
            <geometry>
                <mesh filename="package://fanuc_description/meshes/visual/link_0.dae" />
            </geometry>
        </visual>
        <collision>
            <geometry>
                <mesh filename="package://fanuc_description/meshes/collision/link_0.stl" />
            </geometry>
        </collision>
    </link>

    <joint name="joint1" type="revolute">
        <parent link="base_link"/>
        <child link="link1"/>
        <axis xyz="0 0 1"/>
        <origin xyz="0 0 0" rpy="0 0 0"/>
        <limit lower="-3.228" upper="3.228" effort="12" velocity="3.141"/>
    </joint>

    <link name="link1">
        <visual>
             <geometry>
                <mesh filename="package://fanuc_description/meshes/visual/link_1.dae" />
            </geometry>
        </visual>
        <collision>
            <geometry>
                <mesh filename="package://fanuc_description/meshes/collision/link_1.stl" />
            </geometry>
        </collision>
    </link>

    <joint name="joint2" type="revolute">
        <parent link="link1"/>
        <child link="link2"/>
        <axis xyz="0 0 1"/>
        <origin xyz="0.15 0 0.525" rpy="1.5708 0 0"/>
        <limit lower="-2.268" upper="2.268" effort="12" velocity="3.14"/>
    </joint>

    <link name="link2">
        <visual>
            <origin xyz="-0.15 -0.525 0" rpy="-1.5708 0 0"/>
            <geometry>
               <mesh filename="package://fanuc_description/meshes/visual/link_2.dae" />
           </geometry>
       </visual>
       <collision>
           <origin xyz="-0.15 -0.525 0" rpy="-1.5708 0 0"/>
           <geometry>
               <mesh filename="package://fanuc_description/meshes/collision/link_2.stl" />
           </geometry>
       </collision>
    </link>

    <joint name="joint3" type="revolute">
        <parent link="link2"/>
        <child link="link3"/>
        <axis xyz="0 0 1"/>
        <origin xyz="0 0.79 0" rpy="0 0 1.5708"/>
        <limit lower="-3.996" upper="3.996" effort="12" velocity="3.490"/>
    </joint>


    <link name="link3">
        <visual>
            <origin xyz="-1.315 0.15 0" rpy="-1.5708 0 -1.5708"/>  <!-- 1.315 = 0.525 + 0.790 (vedi robot datasheet)-->
            <geometry>
                <mesh filename="package://fanuc_description/meshes/visual/link_3.dae" />
            </geometry>
        </visual>
        <collision>
            <origin xyz="-1.315 0.15 0" rpy="-1.5708 0 -1.5708"/>  <!-- 1.315 = 0.525 + 0.790 (vedi robot datasheet)-->
            <geometry>
                <mesh filename="package://fanuc_description/meshes/collision/link_3.stl" />
            </geometry>
        </collision>
    </link>

    <joint name="joint4" type="revolute">
        <parent link="link3"/>
        <child link="link4"/>
        <axis xyz="0 0 1"/>
        <origin xyz="0.15 0 0" rpy="1.5708 0 0"/>
        <limit lower="-3.490" upper="3.490" effort="110" velocity="6.108"/>
    </joint>

    <link name="link4">
        <visual>
            <origin xyz="1.465 0.0 -0.15" rpy="0 -1.5708 0.0"/>
            <geometry>
                <mesh filename="package://fanuc_description/meshes/visual/link_4.dae" />
            </geometry>
        </visual>
        <collision>
            <origin xyz="1.465 0.0 -0.15" rpy="0 -1.5708 0.0"/>
            <geometry>
                <mesh filename="package://fanuc_description/meshes/collision/link_4.stl" />
            </geometry>
        </collision>
    </link>

    <joint name="joint5" type="revolute">
        <parent link="link4"/>
        <child link="link5"/>
        <axis xyz="0 0 1"/>
        <origin xyz="0 0 0.86" rpy="1.5708 0 0"/>
        <limit lower="-2.443" upper="2.443" effort="110" velocity="6.108"/>
    </joint>

    <link name="link5">
        <visual>
            <origin xyz="-1.465 -1.01 0" rpy="1.5708 0 1.5708"/>  <!-- 0.86 + 0.1 = 1.01;  0.525+0.79+0.15 = 1.465-->
            <geometry>
                <mesh filename="package://fanuc_description/meshes/visual/link_5.dae" />
            </geometry>
        </visual>
        <collision>
            <origin xyz="-1.465 -1.01 0" rpy="1.5708 0 1.5708"/>  <!-- 0.86 + 0.1 = 1.01;  0.525+0.79+0.15 = 1.465-->
            <geometry>
                <mesh filename="package://fanuc_description/meshes/collision/link_5.stl" />
            </geometry>
        </collision>
    </link>

    <joint name="joint6" type="revolute">
        <parent link="link5"/>
        <child link="link6"/>
        <axis xyz="0 0 1"/>
        <origin xyz="0 0.1 0" rpy="-1.5708 0 0"/>
        <limit lower="-7.85" upper="7.85" effort="60" velocity="6.981"/>
    </joint>

    <link name="link6">
        <visual>
            <origin xyz="0 0 0" rpy="0 0 1.5708"/>  <!-- 0.86 + 0.1 = 1.01;  0.525+0.79+0.15 = 1.465-->
            <geometry>
                <mesh filename="package://fanuc_description/meshes/visual/link_6.dae" />
            </geometry>
        </visual>
        <collision>
            <origin xyz="0 0 0" rpy="0 0 1.5708"/>  <!-- 0.86 + 0.1 = 1.01;  0.525+0.79+0.15 = 1.465-->
            <geometry>
                <mesh filename="package://fanuc_description/meshes/collision/link_6.stl" />
            </geometry>
        </collision>
    </link>

    <joint name="flange" type="fixed">
        <parent link="link6"/>
        <child link="flange"/>
        <axis xyz="0 0 1"/>
        <origin xyz="0 0 0" rpy="0 0 0"/>
    </joint>

    <link name="flange"/>

</robot>