<?xml version="1.0" encoding="UTF-8"?>

<robot name="fanuc">
    <link name="base_link">
        
    </link>

    <joint name="joint1" type="revolute">
        <parent link="base_link"/>
        <child link="link1"/>
        <axis xyz="0 0 1"/>
        <origin xyz="0 0 0" rpy="0 0 0"/>
        <limit lower="-2.967" upper="2.967" effort="12" velocity="2.443"/>
    </joint>

    <link name="link1">

    </link>

    <joint name="joint2" type="revolute">
        <parent link="link1"/>
        <child link="link2"/>
        <axis xyz="0 0 1"/>
        <origin xyz="0.15 0 0.525" rpy="1.5708 0 0"/>
        <limit lower="-2.967" upper="2.967" effort="12" velocity="2.443"/>
    </joint>

    <link name="link2">

    </link>

    <joint name="joint3" type="revolute">
        <parent link="link2"/>
        <child link="link3"/>
        <axis xyz="0 0 1"/>
        <origin xyz="0 0.79 0" rpy="0 0 1.5708"/>
        <limit lower="-2.967" upper="2.967" effort="12" velocity="2.443"/>
    </joint>


    <link name="link3">

    </link>

    <joint name="joint4" type="revolute">
        <parent link="link3"/>
        <child link="link4"/>
        <axis xyz="0 0 1"/>
        <origin xyz="0.15 0 0" rpy="1.5708 0 0"/>
        <limit lower="-2.967" upper="2.967" effort="12" velocity="2.443"/>
    </joint>

    <link name="link4">
        
    </link>

    <joint name="joint5" type="revolute">
        <parent link="link4"/>
        <child link="link5"/>
        <axis xyz="0 0 1"/>
        <origin xyz="0 0 0.86" rpy="0 0 0"/>
        <limit lower="-2.967" upper="2.967" effort="12" velocity="2.443"/>
    </joint>

    <link name="link5">
        
    </link>

    <joint name="joint6" type="revolute">
        <parent link="link5"/>
        <child link="link6"/>
        <axis xyz="0 0 1"/>
        <origin xyz="0 0 0.1" rpy="0 0 0"/>
        <limit lower="-2.967" upper="2.967" effort="12" velocity="2.443"/>
    </joint>

    <link name="link6">
        
    </link>

    <joint name="flange" type="fixed">
        <parent link="link6"/>
        <child link="flange"/>
        <axis xyz="0 0 1"/>
        <origin xyz="0 0 0" rpy="0 0 0"/>
        <limit lower="-2.967" upper="2.967" effort="12" velocity="2.443"/>
    </joint>

    <link name="flange">
        
    </link>

</robot>